var django_2contrib_2gis_2gdal_2error_8py =
[
    [ "django.contrib.gis.gdal.error.GDALException", "classdjango_1_1contrib_1_1gis_1_1gdal_1_1error_1_1_g_d_a_l_exception.html", null ],
    [ "django.contrib.gis.gdal.error.SRSException", "classdjango_1_1contrib_1_1gis_1_1gdal_1_1error_1_1_s_r_s_exception.html", null ],
    [ "django.contrib.gis.gdal.error.check_err", "namespacedjango_1_1contrib_1_1gis_1_1gdal_1_1error.html#ae3834d512de382c4d0fe698e5700a089", null ],
    [ "django.contrib.gis.gdal.error.CPLERR_DICT", "namespacedjango_1_1contrib_1_1gis_1_1gdal_1_1error.html#ac1109414546b8b8a5f38223e97ff096d", null ],
    [ "django.contrib.gis.gdal.error.ERR_NONE", "namespacedjango_1_1contrib_1_1gis_1_1gdal_1_1error.html#a266297e08d1fad5fda333ad5c63bb30d", null ],
    [ "django.contrib.gis.gdal.error.OGRERR_DICT", "namespacedjango_1_1contrib_1_1gis_1_1gdal_1_1error.html#ae2d9457224d2539d70315f073d02cfc2", null ]
];